Workbook

Sheet Comparison
A1: Scenario comparison — Total transport energy consumption
A3: Scenario | B3: Year | C3: Total [MJ/day] | D3: Total [GWh/day] | E3: Total [TJ/day]
A4: Current scenario (2024 fleet) | B4: 2024 | C4: =Current_2024!C59 -> 382749.78 | D4: =Current_2024!C59/3600000 -> 0.10631938 | E4: =Current_2024!C59/1000000 -> 0.38274978
A5: 2030 scenario (55% EV) | B5: 2030 | C5: =Scenario_2030!C59 -> 245822.88 | D5: =Scenario_2030!C59/3600000 -> 0.068284133 | E5: =Scenario_2030!C59/1000000 -> 0.24582288
A6: 2050 scenario (100% EV) | B6: 2050 | C6: =Scenario_2050!C59 -> 155984.3 | D6: =Scenario_2050!C59/3600000 -> 0.043328973 | E6: =Scenario_2050!C59/1000000 -> 0.1559843
A9: How to use this workbook
A10: 1. Open each scenario sheet (Current_2024, Scenario_2030, Scenario_2050).
A11: 2. Enter the four VKT values (II, IE, EI, EE) in the yellow cells under 'VKT INPUTS — USER FILLS THESE CELLS'.
A12: 3. The attributed VKT, EV and conventional energy components, and total are computed automatically.
A13: 4. This Comparison sheet shows the side-by-side total for the three scenarios in MJ, GWh, and TJ.
A14: 5. To change a coefficient (e.g. B = 0.80) or a consumption factor, edit the cell directly on the relevant scenario sheet.
A15: 6. Each parameter has its source noted in the 'Source / Note' column for traceability.

Sheet Current_2024
A1: Current scenario (2024 Gorbeialdea fleet)
A3: FLEET COMPOSITION
A4: Parameter | B4: Unit | C4: Value | D4: Source / Note
A5: EV fleet share (%EV) | B5: [-] | C5: 0.01395 | D5: Total share of fleet that is electric
A6: Conventional fleet share (%Conv) | B6: [-] | C6: 0.98605 | D6: Total share of fleet on conventional fuels
A8: EV SUB-FLEET WEIGHT SHARES (sum to 1)
A9: Light passenger car BEV share (WLE) | B9: [-] | C9: 1
A10: Light commercial BEV share (WLCE) | B10: [-] | C10: 0
A11: Heavy duty BEV share (WHE) | B11: [-] | C11: 0
A12: Sum of EV sub-fleet shares (must = 1) | B12: [-] | C12: =C9+C10+C11 -> 1
A14: CONVENTIONAL SUB-FLEET SHARES ( In column C for all trip types and in D for through trips)
A15: Heavy diesel share (WHD) | B15: [-] | C15: 0.09 | D15: 0.15
A16: Light commercial diesel share (WLCD) | B16: [-] | C16: 0.1152 | D16: =ROUND((0.85/0.91)*C16, 5) -> 0.1076
A17: Light commercial petrol share (WLCG) | B17: [-] | C17: 0.0128 | D17: =ROUND((0.85/0.91)*C17, 5) -> 0.01196
A18: Light passenger car diesel share (WLD) | B18: [-] | C18: 0.4113 | D18: =ROUND((0.85/0.91)*C18, 5) -> 0.38418
A19: Light passenger car petrol share (WLG) | B19: [-] | C19: 0.3655 | D19: =ROUND((0.85/0.91)*C19, 5) -> 0.3414
A20: Light passenger car LPG share (WLL) | B20: [-] | C20: 0.0052 | D20: =ROUND((0.85/0.91)*C20, 5) -> 0.00486
A21: Sum of conventional sub-fleet shares (must = 1) | B21: [-] | C21: =SUM(C15:C20) -> 1 | D21: =SUM(D15:D20) -> 1
A23: ENERGY CONSUMPTION FACTORS
A24: Parameter | B24: Unit | C24: Value | D24: Source / Note
A25: Light diesel passenger car (FLD) | B25: MJ/km | C25: 2.43 | D25: EMEP/EEA Tier 1, Table 3-15 (56.8 g/km × 42.695 MJ/kg)
A26: Light commercial diesel (FLCD) | B26: MJ/km | C26: 3.37 | D26: EMEP/EEA Tier 1, Table 3-15 (79.0 g/km × 42.695 MJ/kg)
A27: Light petrol passenger car (FLG) | B27: MJ/km | C27: 2.71 | D27: EMEP/EEA Tier 1, Table 3-15 (61.9 g/km × 43.774 MJ/kg)
A28: Light commercial petrol (FLCG) | B28: MJ/km | C28: 3.17 | D28: EMEP/EEA Tier 1, Table 3-15 (72.5 g/km × 43.774 MJ/kg)
A29: Light LPG passenger car (FLL) | B29: MJ/km | C29: 2.71 | D29: EMEP/EEA Tier 1, Table 3-15 (58.1 g/km × 46.564 MJ/kg)
A30: Heavy diesel truck (FHD) | B30: MJ/km | C30: 9.26 | D30: EMEP/EEA Tier 1, Table 3-15 (216.8 g/km × 42.695 MJ/kg)
A31: Light passenger car BEV (FLE) | B31: MJ/km | C31: 0.69 | D31: EMEP/EEA Appendix 4 Tier 3 — segment average
A32: Light commercial BEV (FLCE) | B32: MJ/km | C32: 0.86 | D32: EMEP/EEA Appendix 4 Tier 3 — segment average
A33: Heavy duty BEV (FHE) | B33: MJ/km | C33: 3.97 | D33: JEC TTW v5 HDV — Group 4/5 average
A35: TRIP ALLOCATION COEFFICIENTS
A36: Parameter | B36: Unit | C36: Value | D36: Source / Note
A37: II allocation (A) | B37: [-] | C37: 1 | D37: Internal-Internal trips: 100% to region
A38: IE allocation, EVs (B) | B38: [-] | C38: 0.8 | D38: Home-end charging share — Hardman 2018; ChargeUp Europe 2023
A39: EI allocation, EVs (C) | B39: [-] | C39: 0.2 | D39: Destination-end charging share — Hardman 2018; ChargeUp Europe 2023
A40: IE allocation, conv. (B^) | B40: [-] | C40: 0.5 | D40: Symmetric trip-end allocation — IPCC 2006 Vol.2 Ch.3 (bottom-up convention)
A41: EI allocation, conv. (C^) | B41: [-] | C41: 0.5 | D41: Symmetric trip-end allocation — IPCC 2006 Vol.2 Ch.3 (bottom-up convention)
A42: EE allocation (D) | B42: [-] | C42: 0.05 | D42: Highway charging/refuelling share — Hardman 2018
A44: VKT INPUTS — USER FILLS THESE CELLS
A45: Parameter | B45: Unit | C45: Value | D45: Note
A46: Internal-Internal VKT (II) | B46: [veh-km] | C46: 0 | D46: Enter VKT value (left blank for user input)
...

Sheet Scenario_2030
A1: 2030 scenario (55% EV, 45% conventional)
A3: FLEET COMPOSITION
A4: Parameter | B4: Unit | C4: Value | D4: Source / Note
A5: EV fleet share (%EV) | B5: [-] | C5: 0.55 | D5: Total share of fleet that is electric
A6: Conventional fleet share (%Conv) | B6: [-] | C6: 0.45 | D6: Total share of fleet on conventional fuels
A8: EV SUB-FLEET WEIGHT SHARES ( In column C for all trip types and in D for through trips)
A9: Light passenger car BEV share (WLE) | B9: [-] | C9: 0.78 | D9: =ROUND((0.85/0.91)*C9, 4) -> 0.7286
A10: Light commercial BEV share (WLCE) | B10: [-] | C10: 0.13 | D10: =ROUND((0.85/0.91)*C10, 4) -> 0.1214
A11: Heavy duty BEV share (WHE) | B11: [-] | C11: 0.09 | D11: 0.15
A12: Sum of EV sub-fleet shares (must = 1) | B12: [-] | C12: =C9+C10+C11 -> 1 | D12: =SUM(D9,D11,D10) -> 1
A14: CONVENTIONAL SUB-FLEET SHARES ( In column C for all trip types and in D for through trips)
A15: Heavy diesel share (WHD) | B15: [-] | C15: 0.09 | D15: 0.15
A16: Light commercial diesel share (WLCD) | B16: [-] | C16: 0.1152 | D16: =ROUND((0.85/0.91)*C16, 5) -> 0.1076
A17: Light commercial petrol share (WLCG) | B17: [-] | C17: 0.0128 | D17: =ROUND((0.85/0.91)*C17, 5) -> 0.01196
A18: Light passenger car diesel share (WLD) | B18: [-] | C18: 0.4113 | D18: =ROUND((0.85/0.91)*C18, 5) -> 0.38418
A19: Light passenger car petrol share (WLG) | B19: [-] | C19: 0.3655 | D19: =ROUND((0.85/0.91)*C19, 5) -> 0.3414
A20: Light passenger car LPG share (WLL) | B20: [-] | C20: 0.0052 | D20: =ROUND((0.85/0.91)*C20, 5) -> 0.00486
A21: Sum of conventional sub-fleet shares (must = 1) | B21: [-] | C21: =SUM(C15:C20) -> 1 | D21: =SUM(D15:D20) -> 1
A23: ENERGY CONSUMPTION FACTORS
A24: Parameter | B24: Unit | C24: Value | D24: Source / Note
A25: Light diesel passenger car (FLD) | B25: MJ/km | C25: 2.43 | D25: EMEP/EEA Tier 1, Table 3-15 (56.8 g/km × 42.695 MJ/kg)
A26: Light commercial diesel (FLCD) | B26: MJ/km | C26: 3.37 | D26: EMEP/EEA Tier 1, Table 3-15 (79.0 g/km × 42.695 MJ/kg)
A27: Light petrol passenger car (FLG) | B27: MJ/km | C27: 2.71 | D27: EMEP/EEA Tier 1, Table 3-15 (61.9 g/km × 43.774 MJ/kg)
A28: Light commercial petrol (FLCG) | B28: MJ/km | C28: 3.17 | D28: EMEP/EEA Tier 1, Table 3-15 (72.5 g/km × 43.774 MJ/kg)
A29: Light LPG passenger car (FLL) | B29: MJ/km | C29: 2.71 | D29: EMEP/EEA Tier 1, Table 3-15 (58.1 g/km × 46.564 MJ/kg)
A30: Heavy diesel truck (FHD) | B30: MJ/km | C30: 9.26 | D30: EMEP/EEA Tier 1, Table 3-15 (216.8 g/km × 42.695 MJ/kg)
A31: Light passenger car BEV (FLE) | B31: MJ/km | C31: 0.69 | D31: EMEP/EEA Appendix 4 Tier 3 — segment average
A32: Light commercial BEV (FLCE) | B32: MJ/km | C32: 0.86 | D32: EMEP/EEA Appendix 4 Tier 3 — segment average
A33: Heavy duty BEV (FHE) | B33: MJ/km | C33: 3.97 | D33: JEC TTW v5 HDV — Group 4/5 average
A35: TRIP ALLOCATION COEFFICIENTS
A36: Parameter | B36: Unit | C36: Value | D36: Source / Note
A37: II allocation (A) | B37: [-] | C37: 1 | D37: Internal-Internal trips: 100% to region
A38: IE allocation, EVs (B) | B38: [-] | C38: 0.8 | D38: Home-end charging share — Hardman 2018; ChargeUp Europe 2023
A39: EI allocation, EVs (C) | B39: [-] | C39: 0.2 | D39: Destination-end charging share — Hardman 2018; ChargeUp Europe 2023
A40: IE allocation, conv. (B^) | B40: [-] | C40: 0.5 | D40: Symmetric trip-end allocation — IPCC 2006 Vol.2 Ch.3 (bottom-up convention)
A41: EI allocation, conv. (C^) | B41: [-] | C41: 0.5 | D41: Symmetric trip-end allocation — IPCC 2006 Vol.2 Ch.3 (bottom-up convention)
A42: EE allocation (D) | B42: [-] | C42: 0.05 | D42: Highway charging/refuelling share — Hardman 2018
A44: VKT INPUTS — USER FILLS THESE CELLS
A45: Parameter | B45: Unit | C45: Value | D45: Note
A46: Internal-Internal VKT (II) | B46: [veh-km] | C46: 0 | D46: Enter VKT value (left blank for user input)
...

Sheet Scenario_2050
A1: 2050 scenario (100% EV)
A3: FLEET COMPOSITION
A4: Parameter | B4: Unit | C4: Value | D4: Source / Note
A5: EV fleet share (%EV) | B5: [-] | C5: 0.9 | D5: Total share of fleet that is electric
A6: Conventional fleet share (%Conv) | B6: [-] | C6: 0.1 | D6: Total share of fleet on conventional fuels
A8: EV SUB-FLEET WEIGHT SHARES ( In column C for all trip types and in D for through trips)
A9: Light passenger car BEV share (WLE) | B9: [-] | C9: 0.78 | D9: =ROUND((0.85/0.91)*C9, 4) -> 0.7286
A10: Light commercial BEV share (WLCE) | B10: [-] | C10: 0.13 | D10: =ROUND((0.85/0.91)*C10, 4) -> 0.1214
A11: Heavy duty BEV share (WHE) | B11: [-] | C11: 0.09 | D11: 0.15
A12: Sum of EV sub-fleet shares (must = 1) | B12: [-] | C12: =C9+C10+C11 -> 1 | D12: =SUM(D9,D11,D10) -> 1
A14: CONVENTIONAL SUB-FLEET SHARES ( In column C for all trip types and in D for through trips)
A15: Heavy diesel share (WHD) | B15: [-] | C15: 0.09 | D15: 0.15
A16: Light commercial diesel share (WLCD) | B16: [-] | C16: 0.1152 | D16: =ROUND((0.85/0.91)*C16, 5) -> 0.1076
A17: Light commercial petrol share (WLCG) | B17: [-] | C17: 0.0128 | D17: =ROUND((0.85/0.91)*C17, 5) -> 0.01196
A18: Light passenger car diesel share (WLD) | B18: [-] | C18: 0.4113 | D18: =ROUND((0.85/0.91)*C18, 5) -> 0.38418
A19: Light passenger car petrol share (WLG) | B19: [-] | C19: 0.3655 | D19: =ROUND((0.85/0.91)*C19, 5) -> 0.3414
A20: Light passenger car LPG share (WLL) | B20: [-] | C20: 0.0052 | D20: =ROUND((0.85/0.91)*C20, 5) -> 0.00486
A21: Sum of conventional sub-fleet shares (must = 1) | B21: [-] | C21: =SUM(C15:C20) -> 1 | D21: =SUM(D15:D20) -> 1
A23: ENERGY CONSUMPTION FACTORS
A24: Parameter | B24: Unit | C24: Value | D24: Source / Note
A25: Light diesel passenger car (FLD) | B25: MJ/km | C25: 2.43 | D25: EMEP/EEA Tier 1, Table 3-15 (56.8 g/km × 42.695 MJ/kg)
A26: Light commercial diesel (FLCD) | B26: MJ/km | C26: 3.37 | D26: EMEP/EEA Tier 1, Table 3-15 (79.0 g/km × 42.695 MJ/kg)
A27: Light petrol passenger car (FLG) | B27: MJ/km | C27: 2.71 | D27: EMEP/EEA Tier 1, Table 3-15 (61.9 g/km × 43.774 MJ/kg)
A28: Light commercial petrol (FLCG) | B28: MJ/km | C28: 3.17 | D28: EMEP/EEA Tier 1, Table 3-15 (72.5 g/km × 43.774 MJ/kg)
A29: Light LPG passenger car (FLL) | B29: MJ/km | C29: 2.71 | D29: EMEP/EEA Tier 1, Table 3-15 (58.1 g/km × 46.564 MJ/kg)
A30: Heavy diesel truck (FHD) | B30: MJ/km | C30: 9.26 | D30: EMEP/EEA Tier 1, Table 3-15 (216.8 g/km × 42.695 MJ/kg)
A31: Light passenger car BEV (FLE) | B31: MJ/km | C31: 0.69 | D31: EMEP/EEA Appendix 4 Tier 3 — segment average
A32: Light commercial BEV (FLCE) | B32: MJ/km | C32: 0.86 | D32: EMEP/EEA Appendix 4 Tier 3 — segment average
A33: Heavy duty BEV (FHE) | B33: MJ/km | C33: 3.97 | D33: JEC TTW v5 HDV — Group 4/5 average
A35: TRIP ALLOCATION COEFFICIENTS
A36: Parameter | B36: Unit | C36: Value | D36: Source / Note
A37: II allocation (A) | B37: [-] | C37: 1 | D37: Internal-Internal trips: 100% to region
A38: IE allocation, EVs (B) | B38: [-] | C38: 0.8 | D38: Home-end charging share — Hardman 2018; ChargeUp Europe 2023
A39: EI allocation, EVs (C) | B39: [-] | C39: 0.2 | D39: Destination-end charging share — Hardman 2018; ChargeUp Europe 2023
A40: IE allocation, conv. (B^) | B40: [-] | C40: 0.5 | D40: Symmetric trip-end allocation — IPCC 2006 Vol.2 Ch.3 (bottom-up convention)
A41: EI allocation, conv. (C^) | B41: [-] | C41: 0.5 | D41: Symmetric trip-end allocation — IPCC 2006 Vol.2 Ch.3 (bottom-up convention)
A42: EE allocation (D) | B42: [-] | C42: 0.05 | D42: Highway charging/refuelling share — Hardman 2018
A44: VKT INPUTS — USER FILLS THESE CELLS
A45: Parameter | B45: Unit | C45: Value | D45: Note
A46: Internal-Internal VKT (II) | B46: [veh-km] | C46: 0 | D46: Enter VKT value (left blank for user input)
...
